[2025-02-17 13:02:31,339] ERROR log 14564 27056 Internal Server Error: /admin/
Traceback (most recent call last):
  File "C:\Users\bilim\Documents\backend\django\SolutionEnterprise\env\Lib\site-packages\django\core\handlers\exception.py", line 55, in inner
    response = get_response(request)
               ^^^^^^^^^^^^^^^^^^^^^
  File "C:\Users\bilim\Documents\backend\django\SolutionEnterprise\env\Lib\site-packages\django\core\handlers\base.py", line 197, in _get_response
    response = wrapped_callback(request, *callback_args, **callback_kwargs)
               ^^^^^^^^^^^^^^^^^^^^^^^^^^^^^^^^^^^^^^^^^^^^^^^^^^^^^^^^^^^^
  File "C:\Users\bilim\Documents\backend\django\SolutionEnterprise\env\Lib\site-packages\django\contrib\admin\sites.py", line 259, in wrapper
    return self.admin_view(view, cacheable)(*args, **kwargs)
           ^^^^^^^^^^^^^^^^^^^^^^^^^^^^^^^^^^^^^^^^^^^^^^^^^
  File "C:\Users\bilim\Documents\backend\django\SolutionEnterprise\env\Lib\site-packages\django\utils\decorators.py", line 188, in _view_wrapper
    result = _process_exception(request, e)
             ^^^^^^^^^^^^^^^^^^^^^^^^^^^^^^
  File "C:\Users\bilim\Documents\backend\django\SolutionEnterprise\env\Lib\site-packages\django\utils\decorators.py", line 186, in _view_wrapper
    response = view_func(request, *args, **kwargs)
               ^^^^^^^^^^^^^^^^^^^^^^^^^^^^^^^^^^^
  File "C:\Users\bilim\Documents\backend\django\SolutionEnterprise\env\Lib\site-packages\django\views\decorators\cache.py", line 80, in _view_wrapper
    response = view_func(request, *args, **kwargs)
               ^^^^^^^^^^^^^^^^^^^^^^^^^^^^^^^^^^^
  File "C:\Users\bilim\Documents\backend\django\SolutionEnterprise\env\Lib\site-packages\django\contrib\admin\sites.py", line 240, in inner
    return view(request, *args, **kwargs)
           ^^^^^^^^^^^^^^^^^^^^^^^^^^^^^^
  File "C:\Users\bilim\Documents\backend\django\SolutionEnterprise\env\Lib\site-packages\unfold\sites.py", line 118, in index
    **self.each_context(request),
      ^^^^^^^^^^^^^^^^^^^^^^^^^^
  File "C:\Users\bilim\Documents\backend\django\SolutionEnterprise\env\Lib\site-packages\unfold\sites.py", line 100, in each_context
    "sidebar_navigation": self.get_sidebar_list(request)
                          ^^^^^^^^^^^^^^^^^^^^^^^^^^^^^^
  File "C:\Users\bilim\Documents\backend\django\SolutionEnterprise\env\Lib\site-packages\unfold\sites.py", line 234, in get_sidebar_list
    for item in group["items"]:
                ~~~~~^^^^^^^^^
KeyError: 'items'
[2025-02-17 13:02:31,340] ERROR basehttp 14564 27056 "GET /admin/ HTTP/1.1" 500 1004
[2025-02-17 13:03:04,255] ERROR log 21976 7496 Internal Server Error: /admin/
Traceback (most recent call last):
  File "C:\Users\bilim\Documents\backend\django\SolutionEnterprise\env\Lib\site-packages\django\core\handlers\exception.py", line 55, in inner
    response = get_response(request)
               ^^^^^^^^^^^^^^^^^^^^^
  File "C:\Users\bilim\Documents\backend\django\SolutionEnterprise\env\Lib\site-packages\django\core\handlers\base.py", line 197, in _get_response
    response = wrapped_callback(request, *callback_args, **callback_kwargs)
               ^^^^^^^^^^^^^^^^^^^^^^^^^^^^^^^^^^^^^^^^^^^^^^^^^^^^^^^^^^^^
  File "C:\Users\bilim\Documents\backend\django\SolutionEnterprise\env\Lib\site-packages\django\contrib\admin\sites.py", line 259, in wrapper
    return self.admin_view(view, cacheable)(*args, **kwargs)
           ^^^^^^^^^^^^^^^^^^^^^^^^^^^^^^^^^^^^^^^^^^^^^^^^^
  File "C:\Users\bilim\Documents\backend\django\SolutionEnterprise\env\Lib\site-packages\django\utils\decorators.py", line 188, in _view_wrapper
    result = _process_exception(request, e)
             ^^^^^^^^^^^^^^^^^^^^^^^^^^^^^^
  File "C:\Users\bilim\Documents\backend\django\SolutionEnterprise\env\Lib\site-packages\django\utils\decorators.py", line 186, in _view_wrapper
    response = view_func(request, *args, **kwargs)
               ^^^^^^^^^^^^^^^^^^^^^^^^^^^^^^^^^^^
  File "C:\Users\bilim\Documents\backend\django\SolutionEnterprise\env\Lib\site-packages\django\views\decorators\cache.py", line 80, in _view_wrapper
    response = view_func(request, *args, **kwargs)
               ^^^^^^^^^^^^^^^^^^^^^^^^^^^^^^^^^^^
  File "C:\Users\bilim\Documents\backend\django\SolutionEnterprise\env\Lib\site-packages\django\contrib\admin\sites.py", line 240, in inner
    return view(request, *args, **kwargs)
           ^^^^^^^^^^^^^^^^^^^^^^^^^^^^^^
  File "C:\Users\bilim\Documents\backend\django\SolutionEnterprise\env\Lib\site-packages\unfold\sites.py", line 118, in index
    **self.each_context(request),
      ^^^^^^^^^^^^^^^^^^^^^^^^^^
  File "C:\Users\bilim\Documents\backend\django\SolutionEnterprise\env\Lib\site-packages\unfold\sites.py", line 100, in each_context
    "sidebar_navigation": self.get_sidebar_list(request)
                          ^^^^^^^^^^^^^^^^^^^^^^^^^^^^^^
  File "C:\Users\bilim\Documents\backend\django\SolutionEnterprise\env\Lib\site-packages\unfold\sites.py", line 234, in get_sidebar_list
    for item in group["items"]:
                ~~~~~^^^^^^^^^
KeyError: 'items'
[2025-02-17 13:03:04,258] ERROR basehttp 21976 7496 "GET /admin/ HTTP/1.1" 500 1004
[2025-02-17 13:05:39,852] ERROR log 24516 24760 Internal Server Error: /admin/shop/contact/
Traceback (most recent call last):
  File "C:\Users\bilim\Documents\backend\django\SolutionEnterprise\env\Lib\site-packages\django\db\backends\utils.py", line 105, in _execute
    return self.cursor.execute(sql, params)
           ^^^^^^^^^^^^^^^^^^^^^^^^^^^^^^^^
  File "C:\Users\bilim\Documents\backend\django\SolutionEnterprise\env\Lib\site-packages\psycopg\cursor.py", line 732, in execute
    raise ex.with_traceback(None)
psycopg.errors.UndefinedColumn: column shop_contact.created_at does not exist
LINE 1: ..."shop_contact"."email", "shop_contact"."message", "shop_cont...
                                                             ^

The above exception was the direct cause of the following exception:

Traceback (most recent call last):
  File "C:\Users\bilim\Documents\backend\django\SolutionEnterprise\env\Lib\site-packages\django\core\handlers\exception.py", line 55, in inner
    response = get_response(request)
               ^^^^^^^^^^^^^^^^^^^^^
  File "C:\Users\bilim\Documents\backend\django\SolutionEnterprise\env\Lib\site-packages\django\core\handlers\base.py", line 197, in _get_response
    response = wrapped_callback(request, *callback_args, **callback_kwargs)
               ^^^^^^^^^^^^^^^^^^^^^^^^^^^^^^^^^^^^^^^^^^^^^^^^^^^^^^^^^^^^
  File "C:\Users\bilim\Documents\backend\django\SolutionEnterprise\env\Lib\site-packages\django\contrib\admin\options.py", line 715, in wrapper
    return self.admin_site.admin_view(view)(*args, **kwargs)
           ^^^^^^^^^^^^^^^^^^^^^^^^^^^^^^^^^^^^^^^^^^^^^^^^^
  File "C:\Users\bilim\Documents\backend\django\SolutionEnterprise\env\Lib\site-packages\django\utils\decorators.py", line 188, in _view_wrapper
    result = _process_exception(request, e)
             ^^^^^^^^^^^^^^^^^^^^^^^^^^^^^^
  File "C:\Users\bilim\Documents\backend\django\SolutionEnterprise\env\Lib\site-packages\django\utils\decorators.py", line 186, in _view_wrapper
    response = view_func(request, *args, **kwargs)
               ^^^^^^^^^^^^^^^^^^^^^^^^^^^^^^^^^^^
  File "C:\Users\bilim\Documents\backend\django\SolutionEnterprise\env\Lib\site-packages\django\views\decorators\cache.py", line 80, in _view_wrapper
    response = view_func(request, *args, **kwargs)
               ^^^^^^^^^^^^^^^^^^^^^^^^^^^^^^^^^^^
  File "C:\Users\bilim\Documents\backend\django\SolutionEnterprise\env\Lib\site-packages\django\contrib\admin\sites.py", line 240, in inner
    return view(request, *args, **kwargs)
           ^^^^^^^^^^^^^^^^^^^^^^^^^^^^^^
  File "C:\Users\bilim\Documents\backend\django\SolutionEnterprise\env\Lib\site-packages\unfold\mixins\action_model_admin.py", line 57, in changelist_view
    return super().changelist_view(request, extra_context)
           ^^^^^^^^^^^^^^^^^^^^^^^^^^^^^^^^^^^^^^^^^^^^^^^
  File "C:\Users\bilim\Documents\backend\django\SolutionEnterprise\env\Lib\site-packages\django\utils\decorators.py", line 48, in _wrapper
    return bound_method(*args, **kwargs)
           ^^^^^^^^^^^^^^^^^^^^^^^^^^^^^
  File "C:\Users\bilim\Documents\backend\django\SolutionEnterprise\env\Lib\site-packages\django\utils\decorators.py", line 188, in _view_wrapper
    result = _process_exception(request, e)
             ^^^^^^^^^^^^^^^^^^^^^^^^^^^^^^
  File "C:\Users\bilim\Documents\backend\django\SolutionEnterprise\env\Lib\site-packages\django\utils\decorators.py", line 186, in _view_wrapper
    response = view_func(request, *args, **kwargs)
               ^^^^^^^^^^^^^^^^^^^^^^^^^^^^^^^^^^^
  File "C:\Users\bilim\Documents\backend\django\SolutionEnterprise\env\Lib\site-packages\django\contrib\admin\options.py", line 2123, in changelist_view
    "selection_note": _("0 of %(cnt)s selected") % {"cnt": len(cl.result_list)},
                                                           ^^^^^^^^^^^^^^^^^^^
  File "C:\Users\bilim\Documents\backend\django\SolutionEnterprise\env\Lib\site-packages\django\db\models\query.py", line 382, in __len__
    self._fetch_all()
  File "C:\Users\bilim\Documents\backend\django\SolutionEnterprise\env\Lib\site-packages\django\db\models\query.py", line 1928, in _fetch_all
    self._result_cache = list(self._iterable_class(self))
                         ^^^^^^^^^^^^^^^^^^^^^^^^^^^^^^^^
  File "C:\Users\bilim\Documents\backend\django\SolutionEnterprise\env\Lib\site-packages\django\db\models\query.py", line 91, in __iter__
    results = compiler.execute_sql(
              ^^^^^^^^^^^^^^^^^^^^^
  File "C:\Users\bilim\Documents\backend\django\SolutionEnterprise\env\Lib\site-packages\django\db\models\sql\compiler.py", line 1562, in execute_sql
    cursor.execute(sql, params)
  File "C:\Users\bilim\Documents\backend\django\SolutionEnterprise\env\Lib\site-packages\django\db\backends\utils.py", line 79, in execute
    return self._execute_with_wrappers(
           ^^^^^^^^^^^^^^^^^^^^^^^^^^^^
  File "C:\Users\bilim\Documents\backend\django\SolutionEnterprise\env\Lib\site-packages\django\db\backends\utils.py", line 92, in _execute_with_wrappers
    return executor(sql, params, many, context)
           ^^^^^^^^^^^^^^^^^^^^^^^^^^^^^^^^^^^^
  File "C:\Users\bilim\Documents\backend\django\SolutionEnterprise\env\Lib\site-packages\django\db\backends\utils.py", line 100, in _execute
    with self.db.wrap_database_errors:
         ^^^^^^^^^^^^^^^^^^^^^^^^^^^^
  File "C:\Users\bilim\Documents\backend\django\SolutionEnterprise\env\Lib\site-packages\django\db\utils.py", line 91, in __exit__
    raise dj_exc_value.with_traceback(traceback) from exc_value
  File "C:\Users\bilim\Documents\backend\django\SolutionEnterprise\env\Lib\site-packages\django\db\backends\utils.py", line 105, in _execute
    return self.cursor.execute(sql, params)
           ^^^^^^^^^^^^^^^^^^^^^^^^^^^^^^^^
  File "C:\Users\bilim\Documents\backend\django\SolutionEnterprise\env\Lib\site-packages\psycopg\cursor.py", line 732, in execute
    raise ex.with_traceback(None)
django.db.utils.ProgrammingError: column shop_contact.created_at does not exist
LINE 1: ..."shop_contact"."email", "shop_contact"."message", "shop_cont...
                                                             ^
[2025-02-17 13:05:39,863] ERROR basehttp 24516 24760 "GET /admin/shop/contact/ HTTP/1.1" 500 1004
[2025-02-17 13:08:21,534] ERROR log 19356 27560 Internal Server Error: /admin/shop/product/add/
Traceback (most recent call last):
  File "C:\Users\bilim\Documents\backend\django\SolutionEnterprise\env\Lib\site-packages\django\contrib\admin\options.py", line 836, in get_form
    return modelform_factory(self.model, **defaults)
           ^^^^^^^^^^^^^^^^^^^^^^^^^^^^^^^^^^^^^^^^^
  File "C:\Users\bilim\Documents\backend\django\SolutionEnterprise\env\Lib\site-packages\django\forms\models.py", line 652, in modelform_factory
    return type(form)(class_name, (form,), form_class_attrs)
           ^^^^^^^^^^^^^^^^^^^^^^^^^^^^^^^^^^^^^^^^^^^^^^^^^
  File "C:\Users\bilim\Documents\backend\django\SolutionEnterprise\env\Lib\site-packages\django\forms\models.py", line 310, in __new__
    fields = fields_for_model(
             ^^^^^^^^^^^^^^^^^
  File "C:\Users\bilim\Documents\backend\django\SolutionEnterprise\env\Lib\site-packages\django\forms\models.py", line 205, in fields_for_model
    raise FieldError(
django.core.exceptions.FieldError: 'created_at' cannot be specified for Product model form as it is a non-editable field

During handling of the above exception, another exception occurred:

Traceback (most recent call last):
  File "C:\Users\bilim\Documents\backend\django\SolutionEnterprise\env\Lib\site-packages\django\core\handlers\exception.py", line 55, in inner
    response = get_response(request)
               ^^^^^^^^^^^^^^^^^^^^^
  File "C:\Users\bilim\Documents\backend\django\SolutionEnterprise\env\Lib\site-packages\django\core\handlers\base.py", line 197, in _get_response
    response = wrapped_callback(request, *callback_args, **callback_kwargs)
               ^^^^^^^^^^^^^^^^^^^^^^^^^^^^^^^^^^^^^^^^^^^^^^^^^^^^^^^^^^^^
  File "C:\Users\bilim\Documents\backend\django\SolutionEnterprise\env\Lib\site-packages\django\contrib\admin\options.py", line 715, in wrapper
    return self.admin_site.admin_view(view)(*args, **kwargs)
           ^^^^^^^^^^^^^^^^^^^^^^^^^^^^^^^^^^^^^^^^^^^^^^^^^
  File "C:\Users\bilim\Documents\backend\django\SolutionEnterprise\env\Lib\site-packages\django\utils\decorators.py", line 188, in _view_wrapper
    result = _process_exception(request, e)
             ^^^^^^^^^^^^^^^^^^^^^^^^^^^^^^
  File "C:\Users\bilim\Documents\backend\django\SolutionEnterprise\env\Lib\site-packages\django\utils\decorators.py", line 186, in _view_wrapper
    response = view_func(request, *args, **kwargs)
               ^^^^^^^^^^^^^^^^^^^^^^^^^^^^^^^^^^^
  File "C:\Users\bilim\Documents\backend\django\SolutionEnterprise\env\Lib\site-packages\django\views\decorators\cache.py", line 80, in _view_wrapper
    response = view_func(request, *args, **kwargs)
               ^^^^^^^^^^^^^^^^^^^^^^^^^^^^^^^^^^^
  File "C:\Users\bilim\Documents\backend\django\SolutionEnterprise\env\Lib\site-packages\django\contrib\admin\sites.py", line 240, in inner
    return view(request, *args, **kwargs)
           ^^^^^^^^^^^^^^^^^^^^^^^^^^^^^^
  File "C:\Users\bilim\Documents\backend\django\SolutionEnterprise\env\Lib\site-packages\django\contrib\admin\options.py", line 1944, in add_view
    return self.changeform_view(request, None, form_url, extra_context)
           ^^^^^^^^^^^^^^^^^^^^^^^^^^^^^^^^^^^^^^^^^^^^^^^^^^^^^^^^^^^^
  File "C:\Users\bilim\Documents\backend\django\SolutionEnterprise\env\Lib\site-packages\unfold\mixins\action_model_admin.py", line 91, in changeform_view
    return super().changeform_view(request, object_id, form_url, extra_context)
           ^^^^^^^^^^^^^^^^^^^^^^^^^^^^^^^^^^^^^^^^^^^^^^^^^^^^^^^^^^^^^^^^^^^^
  File "C:\Users\bilim\Documents\backend\django\SolutionEnterprise\env\Lib\site-packages\django\utils\decorators.py", line 48, in _wrapper
    return bound_method(*args, **kwargs)
           ^^^^^^^^^^^^^^^^^^^^^^^^^^^^^
  File "C:\Users\bilim\Documents\backend\django\SolutionEnterprise\env\Lib\site-packages\django\utils\decorators.py", line 188, in _view_wrapper
    result = _process_exception(request, e)
             ^^^^^^^^^^^^^^^^^^^^^^^^^^^^^^
  File "C:\Users\bilim\Documents\backend\django\SolutionEnterprise\env\Lib\site-packages\django\utils\decorators.py", line 186, in _view_wrapper
    response = view_func(request, *args, **kwargs)
               ^^^^^^^^^^^^^^^^^^^^^^^^^^^^^^^^^^^
  File "C:\Users\bilim\Documents\backend\django\SolutionEnterprise\env\Lib\site-packages\django\contrib\admin\options.py", line 1803, in changeform_view
    return self._changeform_view(request, object_id, form_url, extra_context)
           ^^^^^^^^^^^^^^^^^^^^^^^^^^^^^^^^^^^^^^^^^^^^^^^^^^^^^^^^^^^^^^^^^^
  File "C:\Users\bilim\Documents\backend\django\SolutionEnterprise\env\Lib\site-packages\django\contrib\admin\options.py", line 1838, in _changeform_view
    ModelForm = self.get_form(
                ^^^^^^^^^^^^^^
  File "C:\Users\bilim\Documents\backend\django\SolutionEnterprise\env\Lib\site-packages\django\contrib\admin\options.py", line 838, in get_form
    raise FieldError(
django.core.exceptions.FieldError: 'created_at' cannot be specified for Product model form as it is a non-editable field. Check fields/fieldsets/exclude attributes of class ProductAdmin.
[2025-02-17 13:08:21,542] ERROR basehttp 19356 27560 "GET /admin/shop/product/add/ HTTP/1.1" 500 1004
